<?xml version="1.0" ?>
<!-- =================================================================================== -->
<!-- |    This document was autogenerated by xacro from rosmower.xacro                 | -->
<!-- |    EDITING THIS FILE BY HAND IS NOT RECOMMENDED                                 | -->
<!-- =================================================================================== -->
<robot name="HoverMower">
  <!-- <xacro:include filename="$(find rosmower)/urdf/rosmower_gazebo_plugins.xacro"/>
  -->
  <material name="blue">
    <color rgba="0 0 0.8 1"/>
  </material>
  <material name="black">
    <color rgba="0 0 0 1"/>
  </material>
  <material name="darkgray">
    <color rgba="0.2 0.2 0.2 1"/>
  </material>
  <material name="lightgray">
    <color rgba="0.8 0.8 0.8 1"/>
  </material>
  <material name="white">
    <color rgba="1 1 1 1"/>
  </material>
  <material name="red">
    <color rgba="0.8 0.0 0.0 1.0"/>
  </material>
  <link name="base_footprint">
    <inertial>
      <mass value="8"/>
      <inertia ixx="1.3333333333333332e-06" ixy="0.0" ixz="0.0" iyy="1.3333333333333332e-06" iyz="0.0" izz="1.3333333333333332e-06"/>
    </inertial>
    <visual>
      <origin rpy="0 0 0" xyz="0 0 0"/>
      <material name="white"/>
      <geometry>
        <box size="0.001 0.001 0.001"/>
      </geometry>
    </visual>
  </link>
  <link name="base_link">
    <inertial>
      <mass value="1"/>
      <inertia ixx="0.006541666666666668" ixy="0.0" ixz="0.0" iyy="0.03047466666666667" iyz="0.0" izz="0.023949666666666668"/>
    </inertial>
    <visual>
      <material name="lightgray"/>
      <geometry>
        <mesh filename="package://rosmower/meshes/robot_body.dae"/>
      </geometry>
    </visual>
    <collision>
      <geometry>
        <mesh filename="package://rosmower/meshes/robot_body.dae"/>
      </geometry>
    </collision>
  </link>
  <joint name="base_link_joint" type="fixed">
    <origin rpy="0 0 0" xyz="0 0 0.08"/>
    <parent link="base_footprint"/>
    <child link="base_link"/>
  </joint>
  <link name="left_wheel">
    <visual>
      <material name="darkgray"/>
      <geometry>
        <mesh filename="package://rosmower/meshes/wheel.dae"/>
      </geometry>
    </visual>
    <collision>
      <geometry>
        <mesh filename="package://rosmower/meshes/wheel.dae"/>
      </geometry>
    </collision>
  </link>
  <joint name="left_wheel" type="continuous">
    <axis rpy="0 0 0" xyz="0 1 0"/>
    <parent link="base_link"/>
    <child link="left_wheel"/>
    <origin rpy="0 0 0" xyz="0 0.15000000000000002 0"/>
  </joint>
  <link name="right_wheel">
    <visual>
      <material name="darkgray"/>
      <geometry>
        <mesh filename="package://rosmower/meshes/wheel.dae"/>
      </geometry>
    </visual>
    <collision>
      <geometry>
        <mesh filename="package://rosmower/meshes/wheel.dae"/>
      </geometry>
    </collision>
  </link>
  <joint name="right_wheel" type="continuous">
    <axis rpy="0 0 0" xyz="0 1 0"/>
    <parent link="base_link"/>
    <child link="right_wheel"/>
    <origin rpy="0 0 3.14159" xyz="0 -0.15000000000000002 0"/>
  </joint>
  <joint name="imu_joint" type="fixed">
    <parent link="base_link"/>
    <child link="imu"/>
    <origin rpy="0 0 0" xyz="0.092 0.0 0.105"/>
  </joint>
  <link name="imu"/>
  <joint name="lidar_joint" type="fixed">
    <parent link="base_link"/>
    <child link="lidar_frame"/>
    <origin rpy="0 0 0" xyz="0.242 0.0 0.195"/>
  </joint>
  <link name="lidar_frame" type="fixed"/>
  <joint name="gps_joint" type="fixed">
    <parent link="base_link"/>
    <child link="gps_frame"/>
    <origin rpy="0 0 0" xyz="0.0 0.118 0.202"/>
  </joint>
  <link name="gps_frame" type="fixed"/>
  <joint name="camera_joint" type="fixed">
    <origin rpy="0 0 0" xyz="0.35 0 0.117"/>
    <parent link="base_link"/>
    <child link="camera_link"/>
  </joint>
  <link name="camera_link" type="fixed"/>
  <joint name="perimeter_left_joint" type="fixed">
    <origin rpy="0 0 0" xyz="0.385 0.081 0.025"/>
    <parent link="base_link"/>
    <child link="perimeter_left"/>
  </joint>
  <link name="perimeter_left" type="fixed"/>
  <joint name="perimeter_right_joint" type="fixed">
    <origin rpy="0 0 0" xyz="0.385 -0.081 0.025"/>
    <parent link="base_link"/>
    <child link="perimeter_right"/>
  </joint>
  <link name="perimeter_right" type="fixed"/>
  <joint name="bumper_left_joint" type="fixed">
    <origin rpy="0 0 0" xyz="0.45 0.101 0.040"/>
    <parent link="base_link"/>
    <child link="bumper_left"/>
  </joint>
  <link name="bumper_left" type="fixed"/>
  <joint name="bumper_right_joint" type="fixed">
    <origin rpy="0 0 0" xyz="0.45 -0.101 0.040"/>
    <parent link="base_link"/>
    <child link="bumper_right"/>
  </joint>
  <link name="bumper_right" type="fixed"/>
</robot>

